Workbook

Sheet Summary
B2: 101 Meydenbauer · Comprehensive Project Takeoff
B3: Project 25-048 · Building B · Units B101–B104 · Addendum #1 + coordinated DWV model · Revision 25 Oct 2026
B5: Key quantities
B7: New Schedule 40 ABS (LF) | E7: Tile / stone allowance (SF) | H7: Engineered wood allowance (SF)
B8: =SUMIFS('Master Takeoff'!$I$6:$I$131,'Master Takeoff'!$E$6:$E$131,"DWV - New ABS") -> 311.65031 | E8: =SUMIFS('Master Takeoff'!$I$6:$I$131,'Master Takeoff'!$E$6:$E$131,"Finishes - Tile/Stone") -> 2232 | H8: =SUMIFS('Master Takeoff'!$I$6:$I$131,'Master Takeoff'!$E$6:$E$131,"Finishes - Wood") -> 1784
B11: Concrete repair allowance (SF) | E11: Carpet allowance (SF) | H11: Quartz countertop allowance (SF)
B12: =SUMIFS('Master Takeoff'!$I$6:$I$131,'Master Takeoff'!$E$6:$E$131,"Concrete - Allowance") -> 700 | E12: =SUMIFS('Master Takeoff'!$I$6:$I$131,'Master Takeoff'!$E$6:$E$131,"Finishes - Carpet") -> 60 | H12: =SUMIFS('Master Takeoff'!$I$6:$I$131,'Master Takeoff'!$E$6:$E$131,"Finishes - Countertop") -> 82
B15: Unit summary
B17: Unit | C17: New ABS (LF) | D17: Tile / stone (SF) | E17: Carpet (SF) | F17: Engineered wood (SF) | G17: Quartz (SF) | H17: Base WC R&R (EA) | I17: Alternate tubs (EA)
B18: B101 | C18: =SUMIFS('Master Takeoff'!$I$6:$I$131,'Master Takeoff'!$E$6:$E$131,"DWV - New ABS",'Master Takeoff'!$F$6:$F$131,$B18) -> 72.585922 | D18: =SUMIFS('Master Takeoff'!$I$6:$I$131,'Master Takeoff'!$E$6:$E$131,"Finishes - Tile/Stone",'Master Takeoff'!$F$6:$F$131,$B18) -> 383 | E18: =SUMIFS('Master Takeoff'!$I$6:$I$131,'Master Takeoff'!$E$6:$E$131,"Finishes - Carpet",'Master Takeoff'!$F$6:$F$131,$B18) -> 60 | F18: =SUMIFS('Master Takeoff'!$I$6:$I$131,'Master Takeoff'!$E$6:$E$131,"Finishes - Wood",'Master Takeoff'!$F$6:$F$131,$B18) -> 0 | G18: =SUMIFS('Master Takeoff'!$I$6:$I$131,'Master Takeoff'!$E$6:$E$131,"Finishes - Countertop",'Master Takeoff'!$F$6:$F$131,$B18) -> 0 | H18: =SUMIFS('Master Takeoff'!$I$6:$I$131,'Master Takeoff'!$E$6:$E$131,"Fixtures - Base R&R",'Master Takeoff'!$F$6:$F$131,$B18,'Master Takeoff'!$H$6:$H$131,"Water closets") -> 2 | I18: =SUMIFS('Master Takeoff'!$I$6:$I$131,'Master Takeoff'!$E$6:$E$131,"Alternate - Fixtures",'Master Takeoff'!$F$6:$F$131,$B18,'Master Takeoff'!$H$6:$H$131,"*bathtub*") -> 1
B19: B102 | C19: =SUMIFS('Master Takeoff'!$I$6:$I$131,'Master Takeoff'!$E$6:$E$131,"DWV - New ABS",'Master Takeoff'!$F$6:$F$131,$B19) -> 76.062391 | D19: =SUMIFS('Master Takeoff'!$I$6:$I$131,'Master Takeoff'!$E$6:$E$131,"Finishes - Tile/Stone",'Master Takeoff'!$F$6:$F$131,$B19) -> 452 | E19: =SUMIFS('Master Takeoff'!$I$6:$I$131,'Master Takeoff'!$E$6:$E$131,"Finishes - Carpet",'Master Takeoff'!$F$6:$F$131,$B19) -> 0 | F19: =SUMIFS('Master Takeoff'!$I$6:$I$131,'Master Takeoff'!$E$6:$E$131,"Finishes - Wood",'Master Takeoff'!$F$6:$F$131,$B19) -> 255 | G19: =SUMIFS('Master Takeoff'!$I$6:$I$131,'Master Takeoff'!$E$6:$E$131,"Finishes - Countertop",'Master Takeoff'!$F$6:$F$131,$B19) -> 0 | H19: =SUMIFS('Master Takeoff'!$I$6:$I$131,'Master Takeoff'!$E$6:$E$131,"Fixtures - Base R&R",'Master Takeoff'!$F$6:$F$131,$B19,'Master Takeoff'!$H$6:$H$131,"Water closets") -> 2 | I19: =SUMIFS('Master Takeoff'!$I$6:$I$131,'Master Takeoff'!$E$6:$E$131,"Alternate - Fixtures",'Master Takeoff'!$F$6:$F$131,$B19,'Master Takeoff'!$H$6:$H$131,"*bathtub*") -> 1
B20: B103 | C20: =SUMIFS('Master Takeoff'!$I$6:$I$131,'Master Takeoff'!$E$6:$E$131,"DWV - New ABS",'Master Takeoff'!$F$6:$F$131,$B20) -> 93.30039 | D20: =SUMIFS('Master Takeoff'!$I$6:$I$131,'Master Takeoff'!$E$6:$E$131,"Finishes - Tile/Stone",'Master Takeoff'!$F$6:$F$131,$B20) -> 991 | E20: =SUMIFS('Master Takeoff'!$I$6:$I$131,'Master Takeoff'!$E$6:$E$131,"Finishes - Carpet",'Master Takeoff'!$F$6:$F$131,$B20) -> 0 | F20: =SUMIFS('Master Takeoff'!$I$6:$I$131,'Master Takeoff'!$E$6:$E$131,"Finishes - Wood",'Master Takeoff'!$F$6:$F$131,$B20) -> 0 | G20: =SUMIFS('Master Takeoff'!$I$6:$I$131,'Master Takeoff'!$E$6:$E$131,"Finishes - Countertop",'Master Takeoff'!$F$6:$F$131,$B20) -> 0 | H20: =SUMIFS('Master Takeoff'!$I$6:$I$131,'Master Takeoff'!$E$6:$E$131,"Fixtures - Base R&R",'Master Takeoff'!$F$6:$F$131,$B20,'Master Takeoff'!$H$6:$H$131,"Water closets") -> 2 | I20: =SUMIFS('Master Takeoff'!$I$6:$I$131,'Master Takeoff'!$E$6:$E$131,"Alternate - Fixtures",'Master Takeoff'!$F$6:$F$131,$B20,'Master Takeoff'!$H$6:$H$131,"*bathtub*") -> 1
B21: B104 | C21: =SUMIFS('Master Takeoff'!$I$6:$I$131,'Master Takeoff'!$E$6:$E$131,"DWV - New ABS",'Master Takeoff'!$F$6:$F$131,$B21) -> 69.70161 | D21: =SUMIFS('Master Takeoff'!$I$6:$I$131,'Master Takeoff'!$E$6:$E$131,"Finishes - Tile/Stone",'Master Takeoff'!$F$6:$F$131,$B21) -> 406 | E21: =SUMIFS('Master Takeoff'!$I$6:$I$131,'Master Takeoff'!$E$6:$E$131,"Finishes - Carpet",'Master Takeoff'!$F$6:$F$131,$B21) -> 0 | F21: =SUMIFS('Master Takeoff'!$I$6:$I$131,'Master Takeoff'!$E$6:$E$131,"Finishes - Wood",'Master Takeoff'!$F$6:$F$131,$B21) -> 1529 | G21: =SUMIFS('Master Takeoff'!$I$6:$I$131,'Master Takeoff'!$E$6:$E$131,"Finishes - Countertop",'Master Takeoff'!$F$6:$F$131,$B21) -> 82 | H21: =SUMIFS('Master Takeoff'!$I$6:$I$131,'Master Takeoff'!$E$6:$E$131,"Fixtures - Base R&R",'Master Takeoff'!$F$6:$F$131,$B21,'Master Takeoff'!$H$6:$H$131,"Water closets") -> 2 | I21: =SUMIFS('Master Takeoff'!$I$6:$I$131,'Master Takeoff'!$E$6:$E$131,"Alternate - Fixtures",'Master Takeoff'!$F$6:$F$131,$B21,'Master Takeoff'!$H$6:$H$131,"*bathtub*") -> 1
B22: TOTAL | C22: =SUM(C18:C21) -> 311.65031 | D22: =SUM(D18:D21) -> 2232 | E22: =SUM(E18:E21) -> 60 | F22: =SUM(F18:F21) -> 1784 | G22: =SUM(G18:G21) -> 82 | H22: =SUM(H18:H21) -> 8 | I22: =SUM(I18:I21) -> 4
B25: Workbook map
B27: Master Takeoff | C27: All numeric scope lines, base bid, allowances, testing, closeout and alternates
B28: DWV Model | C28: Route-by-route 3D measurement basis and retained / existing pipe separation
B29: Finish Allowances | C29: All 24 Addendum #1 allowance items and finish descriptions
B30: Scope Register | C30: Execution requirements and inclusions that accompany the quantities
B31: Sources & Assumptions | C31: Precedence, measurement rules, exclusions and field-verification requirements
B32: Quantity reconciliation: 311.65 LF new ABS · 6.13 LF retained prior 4-inch ABS (excluded from new work) · 11.88 CY planning concrete at 5.5-inch thickness (derived, not a separate pay quantity)
B34: CONTROL NOTE — Contract quantities and final accepted in-place measurements govern. Model quantities are coordination-derived and require field verification. This workbook is unpriced and is not a fabrication bill of materials or surveyed as-built.

Sheet Finish Allowances
B2: Contract finish & concrete allowances
B3: Quantities are contract allowances, not final in-place measurements. Addendum #1 supersedes earlier finish descriptions. Installation inclusions are summarized below.
B5: Allowance | C5: Unit | D5: Location | E5: Finish code | F5: Finish / scope description | G5: Quantity | H5: UoM | I5: Takeoff category | J5: Source | K5: Execution inclusion
B6: AL-1a | C6: B101 | D6: Guest Bathroom | E6: PT-6 | F6: Porcelain tile — Evolution Ivory, polished, 12×24, Surface Art | G6: 253 | H6: SF | I6: Finishes - Tile/Stone | J6: Addendum #1 §01 21 00 p.3; SOR p.20 | K6: Remove existing assembly to required substrate; provide specified replacement system, accessories, receiving, handling, installation, overhead and profit.
B7: AL-1b | C7: B101 | D7: Guest Bathroom | E7: PT-7 | F7: Porcelain tile — Evolution Ivory, polished, 2×2, Surface Art | G7: 25 | H7: SF | I7: Finishes - Tile/Stone | J7: Addendum #1 §01 21 00 p.3; SOR p.20 | K7: Remove existing assembly to required substrate; provide specified replacement system, accessories, receiving, handling, installation, overhead and profit.
B8: AL-1c | C8: B101 | D8: Master Bathroom | E8: PT-8 | F8: Porcelain tile — Bernini Bianco, polished, 12×24, MSI Surfaces | G8: 105 | H8: SF | I8: Finishes - Tile/Stone | J8: Addendum #1 §01 21 00 p.3; SOR p.20 | K8: Remove existing assembly to required substrate; provide specified replacement system, accessories, receiving, handling, installation, overhead and profit.
B9: AL-1d | C9: B101 | D9: Master Bathroom | E9: C-1 | F9: Carpet — Knitted Tone Blue 5E938, Colorwall Soft Sand 00105, Shaw Floors | G9: 60 | H9: SF | I9: Finishes - Carpet | J9: Addendum #1 §01 21 00 p.3; SOR p.20 | K9: Remove existing assembly to required substrate; provide specified replacement system, accessories, receiving, handling, installation, overhead and profit.
B10: AL-2a | C10: B102 | D10: Master Bathroom | E10: NS-3 | F10: Marble Statuario, 12×24, honed, Daltile; tub/shower surround and bathroom floor | G10: 62 | H10: SF | I10: Finishes - Tile/Stone | J10: Addendum #1 §01 21 00 p.4; SOR p.21 | K10: Remove existing assembly to required substrate; provide specified replacement system, accessories, receiving, handling, installation, overhead and profit.
B11: AL-2b | C11: B102 | D11: Master Bathroom | E11: PT-9 | F11: Meta Light Gray porcelain, SA06, 2×2, matte; shower floor | G11: 25 | H11: SF | I11: Finishes - Tile/Stone | J11: Addendum #1 §01 21 00 p.4; SOR p.21 | K11: Remove existing assembly to required substrate; provide specified replacement system, accessories, receiving, handling, installation, overhead and profit.
B12: AL-2c | C12: B102 | D12: Guest Bathroom + Laundry | E12: PT-10 | F12: Matte White Octagon / White Dot, 6501, Daltile | G12: 75 | H12: SF | I12: Finishes - Tile/Stone | J12: Addendum #1 §01 21 00 p.4; SOR p.21 | K12: Remove existing assembly to required substrate; provide specified replacement system, accessories, receiving, handling, installation, overhead and profit.
B13: AL-2d | C13: B102 | D13: Guest Bathroom | E13: PT-11 | F13: Hudson Penny Round Cashmere Blue porcelain mosaic, FKOMPR36, Merola | G13: 18 | H13: SF | I13: Finishes - Tile/Stone | J13: Addendum #1 §01 21 00 p.4; SOR p.22 | K13: Remove existing assembly to required substrate; provide specified replacement system, accessories, receiving, handling, installation, overhead and profit.
B14: AL-2e | C14: B102 | D14: Guest Bathroom | E14: PT-12 | F14: Perpetuo Elegant Beige geometric porcelain, PT22, 12×24, Daltile | G14: 128 | H14: SF | I14: Finishes - Tile/Stone | J14: Addendum #1 §01 21 00 p.4; SOR p.22 | K14: Remove existing assembly to required substrate; provide specified replacement system, accessories, receiving, handling, installation, overhead and profit.
B15: AL-2f | C15: B102 | D15: Guest Bathroom | E15: GT-1 | F15: Oceanique Ocean Sparkle Sky Blue glass subway tile, 2×12, Anthology | G15: 16 | H15: SF | I15: Finishes - Tile/Stone | J15: Addendum #1 §01 21 00 p.4; SOR p.22 | K15: Remove existing assembly to required substrate; provide specified replacement system, accessories, receiving, handling, installation, overhead and profit.
B16: AL-2g | C16: B102 | D16: Entrance / Hallway | E16: NS-2 | F16: Pental Pluvium tile; confirm final selection and match with Owner | G16: 128 | H16: SF | I16: Finishes - Tile/Stone | J16: Addendum #1 §01 21 00 p.4 | K16: Remove existing assembly to required substrate; provide specified replacement system, accessories, receiving, handling, installation, overhead and profit.
B17: AL-3a | C17: B102 | D17: Master + Guest Bedrooms | E17: EHF-1 | F17: Engineered hardwood — GW304 European White Oak, Character, 9/16×7.5×75 RL | G17: 255 | H17: SF | I17: Finishes - Wood | J17: Addendum #1 §01 21 00 p.4; SOR p.21 | K17: Remove existing assembly to required substrate; provide specified replacement system, accessories, receiving, handling, installation, overhead and profit.
... B29: AL-8a | C29: B104 | D29: Kitchen | E29: QCT-1 | F29: Pental Quartz countertop — Borghini Polished | G29: 82 | H29: SF | I29: Finishes - Countertop | J29: Addendum #1 §01 21 00 p.6; SOR p.25 | K29: Remove existing assembly to required substrate; provide specified replacement system, accessories, receiving, handling, installation, overhead and profit.

Sheet DWV Model
B2: Model-derived DWV quantities
B3: Three-dimensional pipe centerline lengths from the editable coordination routes. Quantities exclude fitting deductions, procurement waste and unverified field changes. Existing/retained routes are not new ABS.
B5: Unit | C5: Route | D5: Status | E5: Nominal diameter (in) | F5: Role | G5: 3D centerline (LF) | H5: Source | I5: Measurement note
B6: B101 | C6: main_4 | D6: New ABS | E6: 4 | F6: Under-slab main | G6: 45.432263 | H6: Route controls v2 + supplied model generator | I6: 3D centerline; field verify route, invert, fittings and connection points
B7: B101 | C7: branch_3/bath_n | D7: New ABS | E7: 3 | F7: bath n | G7: 5.08999 | H7: Route controls v2 + supplied model generator | I7: 3D centerline; field verify route, invert, fittings and connection points
B8: B101 | C8: branch_3/bath_s | D8: New ABS | E8: 3 | F8: bath s | G8: 4.161407 | H8: Route controls v2 + supplied model generator | I8: 3D centerline; field verify route, invert, fittings and connection points
B9: B101 | C9: branch_3/laundry | D9: New ABS | E9: 3 | F9: laundry | G9: 1.019588 | H9: Route controls v2 + supplied model generator | I9: 3D centerline; field verify route, invert, fittings and connection points
B10: B101 | C10: branch_2/lav_n | D10: New ABS | E10: 2 | F10: lav n | G10: 11.920204 | H10: Route controls v2 + supplied model generator | I10: 3D centerline; field verify route, invert, fittings and connection points
B11: B101 | C11: branch_2/lav_s | D11: New ABS | E11: 2 | F11: lav s | G11: 3.462145 | H11: Route controls v2 + supplied model generator | I11: 3D centerline; field verify route, invert, fittings and connection points
B12: B101 | C12: lateral_6 | D12: New ABS | E12: 6 | F12: Replacement lateral to 18-inch limit | G12: 1.500325 | H12: Route controls v2 + supplied model generator | I12: 3D centerline; field verify route, invert, fittings and connection points
B13: B101 | C13: prior_abs_4 | D13: Retain existing | E13: 4 | F13: Prior ABS remain — excluded from new work | G13: 2.230471 | H13: Route controls v2 + supplied model generator | I13: 3D centerline; field verify route, invert, fittings and connection points
B14: B101 | C14: lateral_6_context | D14: Existing context | E14: 6 | F14: Existing lateral beyond 18-inch limit — excluded | G14: 18.504 | H14: Route controls v2 + supplied model generator | I14: 3D centerline; field verify route, invert, fittings and connection points
B15: B102 | C15: main_4 | D15: New ABS | E15: 4 | F15: Under-slab main | G15: 48.434184 | H15: Route controls v2 + supplied model generator | I15: 3D centerline; field verify route, invert, fittings and connection points
B16: B102 | C16: branch_3/bath_n | D16: New ABS | E16: 3 | F16: bath n | G16: 4.756497 | H16: Route controls v2 + supplied model generator | I16: 3D centerline; field verify route, invert, fittings and connection points
B17: B102 | C17: branch_3/bath_s | D17: New ABS | E17: 3 | F17: bath s | G17: 5.127821 | H17: Route controls v2 + supplied model generator | I17: 3D centerline; field verify route, invert, fittings and connection points
... B41: B104 | C41: lateral_6_context | D41: Existing context | E41: 6 | F41: Existing lateral beyond 18-inch limit — excluded | G41: 18.504 | H41: Route controls v2 + supplied model generator | I41: 3D centerline; field verify route, invert, fittings and connection points
B43: Coordination comparison
B44: Raw modeled trench plan area before overlap (SF) | G44: 496.8256
B45: Contract concrete repair allowance (SF) | G45: 700
B46: Interpretation | C46: The 700 SF contract allowance controls the allowance takeoff. The 496.8 SF raw model area sums overlapping trench primitives and is not a net or payment quantity.

Sheet Master Takeoff
B2: Comprehensive project takeoff
B3: Base bid WP1–WP3, contract allowances, model-derived DWV quantities, fixtures, restoration, closeout and owner alternates. Blank pricing is intentional: this is an unpriced quantity takeoff.
B5: Item | C5: Work product | D5: Division | E5: Takeoff category | F5: Unit | G5: Location | H5: Scope description | I5: Quantity | J5: UoM | K5: Quantity basis | L5: Source | M5: Notes / verification
B6: T-001 | C6: WP1 | D6: 22 — Plumbing | E6: DWV - New ABS | F6: B101 | G6: Under-slab / lateral | H6: New Schedule 40 solid-core ABS, 2-inch nominal | I6: =SUMIFS('DWV Model'!$G$6:$G$41,'DWV Model'!$B$6:$B$41,$F6,'DWV Model'!$D$6:$D$41,"New ABS",'DWV Model'!$E$6:$E$41,2) -> 15.382349 | J6: LF | K6: Model-derived | L6: Addendum #1 SOR pp.7–12; Exhibit A P1.01/P1.02 | M6: 3D centerline; verify routing, inverts and fittings before procurement
B7: T-002 | C7: WP1 | D7: 22 — Plumbing | E7: DWV - New ABS | F7: B101 | G7: Under-slab / lateral | H7: New Schedule 40 solid-core ABS, 3-inch nominal | I7: =SUMIFS('DWV Model'!$G$6:$G$41,'DWV Model'!$B$6:$B$41,$F7,'DWV Model'!$D$6:$D$41,"New ABS",'DWV Model'!$E$6:$E$41,3) -> 10.270985 | J7: LF | K7: Model-derived | L7: Addendum #1 SOR pp.7–12; Exhibit A P1.01/P1.02 | M7: 3D centerline; verify routing, inverts and fittings before procurement
B8: T-003 | C8: WP1 | D8: 22 — Plumbing | E8: DWV - New ABS | F8: B101 | G8: Under-slab / lateral | H8: New Schedule 40 solid-core ABS, 4-inch nominal | I8: =SUMIFS('DWV Model'!$G$6:$G$41,'DWV Model'!$B$6:$B$41,$F8,'DWV Model'!$D$6:$D$41,"New ABS",'DWV Model'!$E$6:$E$41,4) -> 45.432263 | J8: LF | K8: Model-derived | L8: Addendum #1 SOR pp.7–12; Exhibit A P1.01/P1.02 | M8: 3D centerline; verify routing, inverts and fittings before procurement
B9: T-004 | C9: WP1 | D9: 22 — Plumbing | E9: DWV - New ABS | F9: B101 | G9: Under-slab / lateral | H9: New Schedule 40 solid-core ABS, 6-inch nominal | I9: =SUMIFS('DWV Model'!$G$6:$G$41,'DWV Model'!$B$6:$B$41,$F9,'DWV Model'!$D$6:$D$41,"New ABS",'DWV Model'!$E$6:$E$41,6) -> 1.500325 | J9: LF | K9: Model-derived | L9: Addendum #1 SOR pp.7–12; Exhibit A P1.01/P1.02 | M9: 3D centerline; verify routing, inverts and fittings before procurement
B10: T-005 | C10: WP1 | D10: 22 / 09 / 26 | E10: Fixtures - Base R&R | F10: B101 | G10: Ground-floor unit | H10: Kitchen sink / cabinet | I10: 1 | J10: EA | K10: Model + document count | L10: Addendum #1 SOR pp.7–12; Exhibit A P1.01/P1.02 | M10: Remove and reinstall existing sink and cabinet; include drain and p-trap
B11: T-006 | C11: WP1 | D11: 22 / 09 / 26 | E11: Fixtures - Base R&R | F11: B101 | G11: Ground-floor unit | H11: Water closets | I11: 2 | J11: EA | K11: Model + document count | L11: Addendum #1 SOR pp.7–12; Exhibit A P1.01/P1.02 | M11: Remove and reinstall wall-hung WC; carrier/flange connection work as required
B12: T-007 | C12: WP1 | D12: 22 / 09 / 26 | E12: Fixtures - Base R&R | F12: B101 | G12: Ground-floor unit | H12: Bathtubs | I12: 1 | J12: EA | K12: Model + document count | L12: Addendum #1 SOR pp.7–12; Exhibit A P1.01/P1.02 | M12: Remove and reinstall tub and enclosure as required; include drain-waste assembly and p-trap
B13: T-008 | C13: WP1 | D13: 22 / 09 / 26 | E13: Fixtures - Base R&R | F13: B101 | G13: Ground-floor unit | H13: Showers / enclosures | I13: 1 | J13: EA | K13: Model + document count | L13: Addendum #1 SOR pp.7–12; Exhibit A P1.01/P1.02 | M13: Remove and reinstall shower/enclosure as required; include drain-waste assembly and p-trap
B14: T-009 | C14: WP1 | D14: 22 / 09 / 26 | E14: Fixtures - Base R&R | F14: B101 | G14: Ground-floor unit | H14: Lavatories / cabinets | I14: 2 | J14: EA | K14: Model + document count | L14: Addendum #1 SOR pp.7–12; Exhibit A P1.01/P1.02 | M14: Remove and reinstall lavatory and cabinet; include p-trap and required electrical disconnection
B15: T-010 | C15: WP1 | D15: 22 / 09 / 26 | E15: Fixtures - Base R&R | F15: B101 | G15: Ground-floor unit | H15: Washing machines | I15: 1 | J15: EA | K15: Model + document count | L15: Addendum #1 SOR pp.7–12; Exhibit A P1.01/P1.02 | M15: Disconnect, move, reinstall and verify working condition
B16: T-011 | C16: WP1 | D16: 22 / 09 / 26 | E16: Fixtures - Base R&R | F16: B101 | G16: Ground-floor unit | H16: Dryers | I16: 1 | J16: EA | K16: Model + document count | L16: Addendum #1 SOR pp.7–12; Exhibit A P1.01/P1.02 | M16: Move, reinstall and verify working condition
B17: T-012 | C17: WP1 | D17: 22 — Plumbing | E17: DWV - Accessories | F17: B101 | G17: Unit network | H17: Base-of-stack cleanouts | I17: 3 | J17: EA | K17: Model-derived | L17: Addendum #1 SOR pp.7–12; Exhibit A P1.01/P1.02 | M17: Accessible cleanouts at stack bases; final count and location field verify
B18: T-013 | C18: WP1 | D18: 22 — Plumbing | E18: DWV - Accessories | F18: B101 | G18: Unit network | H18: Vertical stack tie-ins | I18: 3 | J18: EA | K18: Model-derived | L18: Addendum #1 SOR pp.7–12; Exhibit A P1.01/P1.02 | M18: New ABS connection to existing stack; expose sufficient vertical pipe; final count and location field verify
B19: T-014 | C19: WP1 | D19: 22 — Plumbing | E19: DWV - Accessories | F19: B101 | G19: Unit network | H19: 4-to-6-inch transition couplings | I19: 1 | J19: EA | K19: Model-derived | L19: Addendum #1 SOR pp.7–12; Exhibit A P1.01/P1.02 | M19: Transition from unit main to replacement lateral; final count and location field verify
B20: T-015 | C20: WP1 | D20: 22 — Plumbing | E20: DWV - Accessories | F20: B101 | G20: Unit network | H20: Exterior lateral cleanouts | I20: 1 | J20: EA | K20: Model-derived | L20: Addendum #1 SOR pp.7–12; Exhibit A P1.01/P1.02 | M20: Coordinated exterior cleanout and pad; final count and location field verify
B21: T-016 | C21: WP1 | D21: 22 — Plumbing | E21: DWV - Accessories | F21: B101 | G21: Unit network | H21: Water-test plugs | I21: 1 | J21: EA | K21: Model-derived | L21: Addendum #1 SOR pp.7–12; Exhibit A P1.01/P1.02 | M21: Temporary isolation for leak testing; final count and location field verify
B22: T-017 | C22: WP2 | D22: 22 — Plumbing | E22: Testing | F22: B101 | G22: Finished drain system | H22: Leak test with water per City of Bellevue; do not air test | I22: 1 | J22: TEST | K22: Document + model count | L22: Addendum #1 SOR p.28; Exhibit A testing notes | M22: Coordinate inspection and acceptance before concealment
B23: T-018 | C23: WP1 | D23: 22 — Plumbing | E23: DWV - New ABS | F23: B102 | G23: Under-slab / lateral | H23: New Schedule 40 solid-core ABS, 2-inch nominal | I23: =SUMIFS('DWV Model'!$G$6:$G$41,'DWV Model'!$B$6:$B$41,$F23,'DWV Model'!$D$6:$D$41,"New ABS",'DWV Model'!$E$6:$E$41,2) -> 13.759218 | J23: LF | K23: Model-derived | L23: Addendum #1 SOR pp.7–12; Exhibit A P1.01/P1.02 | M23: 3D centerline; verify routing, inverts and fittings before procurement
B24: T-019 | C24: WP1 | D24: 22 — Plumbing | E24: DWV - New ABS | F24: B102 | G24: Under-slab / lateral | H24: New Schedule 40 solid-core ABS, 3-inch nominal | I24: =SUMIFS('DWV Model'!$G$6:$G$41,'DWV Model'!$B$6:$B$41,$F24,'DWV Model'!$D$6:$D$41,"New ABS",'DWV Model'!$E$6:$E$41,3) -> 12.368664 | J24: LF | K24: Model-derived | L24: Addendum #1 SOR pp.7–12; Exhibit A P1.01/P1.02 | M24: 3D centerline; verify routing, inverts and fittings before procurement
B25: T-020 | C25: WP1 | D25: 22 — Plumbing | E25: DWV - New ABS | F25: B102 | G25: Under-slab / lateral | H25: New Schedule 40 solid-core ABS, 4-inch nominal | I25: =SUMIFS('DWV Model'!$G$6:$G$41,'DWV Model'!$B$6:$B$41,$F25,'DWV Model'!$D$6:$D$41,"New ABS",'DWV Model'!$E$6:$E$41,4) -> 48.434184 | J25: LF | K25: Model-derived | L25: Addendum #1 SOR pp.7–12; Exhibit A P1.01/P1.02 | M25: 3D centerline; verify routing, inverts and fittings before procurement
B26: T-021 | C26: WP1 | D26: 22 — Plumbing | E26: DWV - New ABS | F26: B102 | G26: Under-slab / lateral | H26: New Schedule 40 solid-core ABS, 6-inch nominal | I26: =SUMIFS('DWV Model'!$G$6:$G$41,'DWV Model'!$B$6:$B$41,$F26,'DWV Model'!$D$6:$D$41,"New ABS",'DWV Model'!$E$6:$E$41,6) -> 1.500325 | J26: LF | K26: Model-derived | L26: Addendum #1 SOR pp.7–12; Exhibit A P1.01/P1.02 | M26: 3D centerline; verify routing, inverts and fittings before procurement
B27: T-022 | C27: WP1 | D27: 22 / 09 / 26 | E27: Fixtures - Base R&R | F27: B102 | G27: Ground-floor unit | H27: Kitchen sink / cabinet | I27: 1 | J27: EA | K27: Model + document count | L27: Addendum #1 SOR pp.7–12; Exhibit A P1.01/P1.02 | M27: Remove and reinstall existing sink and cabinet; include drain and p-trap
B28: T-023 | C28: WP1 | D28: 22 / 09 / 26 | E28: Fixtures - Base R&R | F28: B102 | G28: Ground-floor unit | H28: Water closets | I28: 2 | J28: EA | K28: Model + document count | L28: Addendum #1 SOR pp.7–12; Exhibit A P1.01/P1.02 | M28: Remove and reinstall wall-hung WC; carrier/flange connection work as required
B29: T-024 | C29: WP1 | D29: 22 / 09 / 26 | E29: Fixtures - Base R&R | F29: B102 | G29: Ground-floor unit | H29: Bathtubs | I29: 1 | J29: EA | K29: Model + document count | L29: Addendum #1 SOR pp.7–12; Exhibit A P1.01/P1.02 | M29: Remove and reinstall tub and enclosure as required; include drain-waste assembly and p-trap
B30: T-025 | C30: WP1 | D30: 22 / 09 / 26 | E30: Fixtures - Base R&R | F30: B102 | G30: Ground-floor unit | H30: Showers / enclosures | I30: 1 | J30: EA | K30: Model + document count | L30: Addendum #1 SOR pp.7–12; Exhibit A P1.01/P1.02 | M30: Remove and reinstall shower/enclosure as required; include drain-waste assembly and p-trap
B31: T-026 | C31: WP1 | D31: 22 / 09 / 26 | E31: Fixtures - Base R&R | F31: B102 | G31: Ground-floor unit | H31: Lavatories / cabinets | I31: 2 | J31: EA | K31: Model + document count | L31: Addendum #1 SOR pp.7–12; Exhibit A P1.01/P1.02 | M31: Remove and reinstall lavatory and cabinet; include p-trap and required electrical disconnection
B32: T-027 | C32: WP1 | D32: 22 / 09 / 26 | E32: Fixtures - Base R&R | F32: B102 | G32: Ground-floor unit | H32: Washing machines | I32: 1 | J32: EA | K32: Model + document count | L32: Addendum #1 SOR pp.7–12; Exhibit A P1.01/P1.02 | M32: Disconnect, move, reinstall and verify working condition
B33: T-028 | C33: WP1 | D33: 22 / 09 / 26 | E33: Fixtures - Base R&R | F33: B102 | G33: Ground-floor unit | H33: Dryers | I33: 1 | J33: EA | K33: Model + document count | L33: Addendum #1 SOR pp.7–12; Exhibit A P1.01/P1.02 | M33: Move, reinstall and verify working condition
B34: T-029 | C34: WP1 | D34: 22 — Plumbing | E34: DWV - Accessories | F34: B102 | G34: Unit network | H34: Base-of-stack cleanouts | I34: 3 | J34: EA | K34: Model-derived | L34: Addendum #1 SOR pp.7–12; Exhibit A P1.01/P1.02 | M34: Accessible cleanouts at stack bases; final count and location field verify
B35: T-030 | C35: WP1 | D35: 22 — Plumbing | E35: DWV - Accessories | F35: B102 | G35: Unit network | H35: Vertical stack tie-ins | I35: 3 | J35: EA | K35: Model-derived | L35: Addendum #1 SOR pp.7–12; Exhibit A P1.01/P1.02 | M35: New ABS connection to existing stack; expose sufficient vertical pipe; final count and location field verify
B36: T-031 | C36: WP1 | D36: 22 — Plumbing | E36: DWV - Accessories | F36: B102 | G36: Unit network | H36: 4-to-6-inch transition couplings | I36: 1 | J36: EA | K36: Model-derived | L36: Addendum #1 SOR pp.7–12; Exhibit A P1.01/P1.02 | M36: Transition from unit main to replacement lateral; final count and location field verify
B37: T-032 | C37: WP1 | D37: 22 — Plumbing | E37: DWV - Accessories | F37: B102 | G37: Unit network | H37: Exterior lateral cleanouts | I37: 1 | J37: EA | K37: Model-derived | L37: Addendum #1 SOR pp.7–12; Exhibit A P1.01/P1.02 | M37: Coordinated exterior cleanout and pad; final count and location field verify
B38: T-033 | C38: WP1 | D38: 22 — Plumbing | E38: DWV - Accessories | F38: B102 | G38: Unit network | H38: Water-test plugs | I38: 1 | J38: EA | K38: Model-derived | L38: Addendum #1 SOR pp.7–12; Exhibit A P1.01/P1.02 | M38: Temporary isolation for leak testing; final count and location field verify
B39: T-034 | C39: WP2 | D39: 22 — Plumbing | E39: Testing | F39: B102 | G39: Finished drain system | H39: Leak test with water per City of Bellevue; do not air test | I39: 1 | J39: TEST | K39: Document + model count | L39: Addendum #1 SOR p.28; Exhibit A testing notes | M39: Coordinate inspection and acceptance before concealment
B40: T-035 | C40: WP1 | D40: 22 — Plumbing | E40: DWV - New ABS | F40: B103 | G40: Under-slab / lateral | H40: New Schedule 40 solid-core ABS, 2-inch nominal | I40: =SUMIFS('DWV Model'!$G$6:$G$41,'DWV Model'!$B$6:$B$41,$F40,'DWV Model'!$D$6:$D$41,"New ABS",'DWV Model'!$E$6:$E$41,2) -> 15.636944 | J40: LF | K40: Model-derived | L40: Addendum #1 SOR pp.7–12; Exhibit A P1.01/P1.02 | M40: 3D centerline; verify routing, inverts and fittings before procurement
B41: T-036 | C41: WP1 | D41: 22 — Plumbing | E41: DWV - New ABS | F41: B103 | G41: Under-slab / lateral | H41: New Schedule 40 solid-core ABS, 3-inch nominal | I41: =SUMIFS('DWV Model'!$G$6:$G$41,'DWV Model'!$B$6:$B$41,$F41,'DWV Model'!$D$6:$D$41,"New ABS",'DWV Model'!$E$6:$E$41,3) -> 13.889694 | J41: LF | K41: Model-derived | L41: Addendum #1 SOR pp.7–12; Exhibit A P1.01/P1.02 | M41: 3D centerline; verify routing, inverts and fittings before procurement
B42: T-037 | C42: WP1 | D42: 22 — Plumbing | E42: DWV - New ABS | F42: B103 | G42: Under-slab / lateral | H42: New Schedule 40 solid-core ABS, 4-inch nominal | I42: =SUMIFS('DWV Model'!$G$6:$G$41,'DWV Model'!$B$6:$B$41,$F42,'DWV Model'!$D$6:$D$41,"New ABS",'DWV Model'!$E$6:$E$41,4) -> 62.273427 | J42: LF | K42: Model-derived | L42: Addendum #1 SOR pp.7–12; Exhibit A P1.01/P1.02 | M42: 3D centerline; verify routing, inverts and fittings before procurement
...

Sheet Scope Register
B2: Scope inclusion & verification register
B3: Companion to the Master Takeoff: requirements that must be carried within the work even where a lump-sum line is used. It is not an exclusion list.
B5: Work product | C5: Division | D5: Scope / requirement | E5: Measurement approach | F5: Source | G5: Required verification / inclusion
B6: WP1 | C6: 22 — Plumbing | D6: Replace the complete DW system from 18 inches outside the foundation through ground-floor slab penetrations to fixtures and existing upper-floor stacks. | E6: LF / EA by modeled routes and fixture groups | F6: Addendum #1 SOR pp.7–8 | G6: Like-in-kind route and sizes; notify Engineer of discrepancies; retain B101 prior kitchen/dining ABS unless otherwise directed.
B7: WP1 | C7: 22 — Plumbing | D7: Vertical stack exposure and approved wye, combination wye / 1⁄8 bend or sanitary tee connections. | E7: Locations + LS fittings | F7: Addendum #1 SOR pp.9–11 | G7: Support above and below cuts; no notch repairs; sufficient straight length for couplings; code-compliant alignment.
B8: WP1 | C8: 22 — Plumbing | D8: Side-sewer connections outside the building, preferably at planter areas avoiding concrete removal. | E8: 4 unit connections / field verify | F8: Addendum #1 SOR p.11 | G8: Existing 6-inch lateral beyond the 18-inch replacement limit and 8-inch side sewer are context / remain, not new replacement.
B9: WP1 | C9: 03 / 31 | D9: Concrete cutting, excavation, bedding, backfill, slab repair and sealer for high-water-table conditions. | E9: 700 SF contract allowance | F9: Addendum #1 AL-7; SOR p.9; §03 30 00 | G9: Coordinate vapor barrier, crystalline permeability-reducing admixture and inspections; actual excavation volume field measure.
B10: WP1 | C10: 07 — Moisture protection | D10: Identify and preserve existing vapor barrier / waterproofing during demolition. | E10: 700 SF net repair + laps/accessories | F10: Addendum #1 SOR p.9 | G10: Notify Architect / Engineer when exposed; install Stegowrap system per manufacturer.
B11: WP1 | C11: 09 — Finishes | D11: Document existing finishes and submit like-for-like or approved comparable replacements. | E11: Contract allowance + field measure | F11: Addendum #1 SOR pp.11, 20–27 | G11: Owner approval; whole wall / room refinishing may be required for seamless match.
B12: WP1 | C12: 09 — Finishes | D12: Tile and stone assemblies, including removal of adhesive, mortar bed and membranes where required. | E12: SF in-place | F12: Addendum #1 §§01 21 00 / 01 22 00 | G12: TCNA-appropriate assembly; vapor primer at slab-on-grade; waterproofing/crack isolation; 25-year system warranty.
B13: WP1 | C13: 09 — Finishes | D13: Engineered hardwood replacement including adhesive, underlayment and accessories removal. | E13: SF in-place | F13: Addendum #1 §§01 21 00 / 01 22 00 | G13: Vapor-mitigating primer and NWFA / manufacturer installation requirements.
B14: WP1 | C14: 09 / 26 | D14: Radiant heated-coil flooring removal and replacement where occurs. | E14: LS / field measure | F14: Addendum #1 SOR p.19; §01 22 00 | G14: 220 V system like-in-kind where reuse is not possible; coordinate electrical work.
B15: WP2 | C15: 22 — Plumbing | D15: Water leak test of each finished drain system to City of Bellevue standards. | E15: 4 tests | F15: Addendum #1 SOR p.28 | G15: Do not air test; provide required inspection and test documentation.
B16: WP3 | C16: 01 — Closeout | D16: Dimensioned as-built drawings, photographs, permits, inspections, tests, correspondence, material lists and maintenance narrative. | E16: 2 hard-copy sets + 3 USB sets | F16: Addendum #1 SOR pp.28–29 | G16: Professional readable drawings; ±2-inch location accuracy; electronic and project-binder formats.
... B21: Alternate 2 | C21: 22 / 09 | D21: Like-in-kind bathtub replacement. | E21: 4 EA | F21: Project Manual §01 23 00 | G21: Owner acceptance required; match existing size, shape, finish and color.

Sheet Sources & Assumptions
B2: Sources, measurement rules & exclusions
B3: Read before using quantities for procurement, pricing or payment. Contract documents control over the coordination model.
B5: Topic | C5: Rule / source / assumption
B6: Contract precedence | C6: Addendum #1 dated 2026-10-16 is treated as superseding earlier bid-form, allowance, unit-price and Scope of Repair information. Project ID 25-048.
B7: Primary sources | C7: 25-048 Addendum 1 (00 41 13, 00 91 13, 01 21 00, 01 22 00 and revised SOR); Project Manual Bid Set 2026-09-28 (01 23 00 and 03 30 00); Exhibit A Waste Re-Pipe Bid Set; Exhibit B precast record drawings.
B8: Model sources | C8: meydenbauer_route_controls_v2.csv and meydenbauer_4d_3pass_v2.py. One model unit equals one foot. Lengths are calculated along connected 3D centerlines, including representative 1/4-inch-per-foot slope.
B9: New ABS measurement | C9: 311.65 LF is the unrounded model total of new 2-, 3-, 4- and 6-inch ABS. It excludes retained prior ABS and existing lateral context. Fitting deductions, vertical removal beyond modeled connections, procurement waste and unforeseeable field changes are not included.
B10: Existing / retained | C10: B101 prior 4-inch ABS: 2.23 LF. B104 prior 4-inch ABS: 3.90 LF. Existing 6-inch lateral context beyond the 18-inch replacement limit: approximately 18.50 LF per unit. These are excluded from new ABS.
B11: Fixture counts | C11: Each unit is represented with 2 WCs, 2 lavatories, 1 bathtub, 1 shower, 1 kitchen sink, 1 washer and 1 dryer. Project totals: 8 WCs, 8 lavatories, 4 tubs, 4 showers, 4 kitchen sinks, 4 washers and 4 dryers. Verify actual fixture configurations and carrier conditions.
B12: Concrete allowance | C12: 700 SF is the contract quantity allowance for concrete cutting, excavation, backfill and repair. The 5.5-inch planning volume of 11.88 CY is derived, not an independent pay quantity. Actual excavation volume, reinforcement, dowels and structural repair require field verification / Engineer protocol.
B13: Model trench area | C13: 496.83 SF is a raw sum of overlapping trench plan primitives. It is not a net area and does not replace the 700 SF allowance or final in-place measurement.
B14: Finish allowances | C14: Tile/stone 2,232 SF; carpet 60 SF; engineered wood 1,784 SF; quartz countertop 82 SF. Floor and wall areas are mixed within tile/stone totals as scheduled; do not assume every square foot is flooring.
B15: Finish selection conflict | C15: AL-6a / EHF-2 contains two product descriptions in Addendum #1. Both are preserved in the workbook; Owner / Architect must confirm the intended selection before ordering.
B16: Pricing | C16: This is an unpriced quantity takeoff. Labor rates, material unit rates, sales tax, escalation, overhead, profit and bid totals are not estimated. Allowance inclusions and unit-price procedures are identified in the scope notes.
... B19: Field verification | C19: Actual routing, invert elevations, fitting counts, stack locations, cleanouts, utility conflicts, wall assemblies, fire ratings, finish boundaries and connection points must be verified before construction. This workbook is not a surveyed as-built or fabrication bill of materials.
